<mujoco model="r1">
  <compiler angle="radian" meshdir="assets"/>
  <default>
    <joint damping="0.05" armature="0.01" frictionloss="0.2"/>
  </default>

  <default>
    <default class="r1">
      <default class="visual">
        <geom type="mesh" density="0" contype="0" conaffinity="0" group="2"/>
      </default>
      <default class="collision">
        <geom type="capsule" priority="1" condim="6" group="3"/>
        <default class="foot_capsule">
          <geom size="0.01"/>
        </default>
      </default>
      <site rgba="1 0 0 1" group="5"/>
    </default>
  </default>

  <asset>
    <mesh name="pelvis_link" file="pelvis_link.STL"/>
    <mesh name="left_hip_pitch_link" file="left_hip_pitch_link.STL"/>
    <mesh name="left_hip_roll_link" file="left_hip_roll_link.STL"/>
    <mesh name="left_hip_yaw_link" file="left_hip_yaw_link.STL"/>
    <mesh name="left_knee_link" file="left_knee_link.STL"/>
    <mesh name="left_knee_collision" file="left_knee_collision.STL"/>
    <mesh name="left_ankle_A_link" file="left_ankle_A_link.STL"/>
    <mesh name="left_ankle_A_rod_link" file="left_ankle_A_rod_link.STL"/>
    <mesh name="left_ankle_B_link" file="left_ankle_B_link.STL"/>
    <mesh name="left_ankle_B_rod_link" file="left_ankle_B_rod_link.STL"/>
    <mesh name="left_ankle_pitch_link" file="left_ankle_pitch_link.STL"/>
    <mesh name="left_ankle_roll_link" file="left_ankle_roll_link.STL"/>
    <mesh name="left_ankle_constraint_A_link" file="left_ankle_constraint_A_link.STL"/>
    <mesh name="left_ankle_constraint_B_link" file="left_ankle_constraint_B_link.STL"/>
    <mesh name="right_hip_pitch_link" file="right_hip_pitch_link.STL"/>
    <mesh name="right_hip_roll_link" file="right_hip_roll_link.STL"/>
    <mesh name="right_hip_yaw_link" file="right_hip_yaw_link.STL"/>
    <mesh name="right_knee_link" file="right_knee_link.STL"/>
    <mesh name="right_knee_collision" file="right_knee_collision.STL"/>
    <mesh name="right_ankle_A_link" file="right_ankle_A_link.STL"/>
    <mesh name="right_ankle_A_rod_link" file="right_ankle_A_rod_link.STL"/>
    <mesh name="right_ankle_B_link" file="right_ankle_B_link.STL"/>
    <mesh name="right_ankle_B_rod_link" file="right_ankle_B_rod_link.STL"/>
    <mesh name="right_ankle_pitch_link" file="right_ankle_pitch_link.STL"/>
    <mesh name="right_ankle_roll_link" file="right_ankle_roll_link.STL"/>
    <mesh name="right_ankle_constraint_A_link" file="right_ankle_constraint_A_link.STL"/>
    <mesh name="right_ankle_constraint_B_link" file="right_ankle_constraint_B_link.STL"/>
    <mesh name="imu_in_pelvis_link" file="imu_in_pelvis_link.STL"/>
    <mesh name="waist_roll_link" file="waist_roll_link.STL"/>
    <mesh name="waist_yaw_link" file="waist_yaw_link.STL"/>
    <mesh name="left_shoulder_pitch_link" file="left_shoulder_pitch_link.STL"/>
    <mesh name="left_shoulder_roll_link" file="left_shoulder_roll_link.STL"/>
    <mesh name="left_shoulder_yaw_link" file="left_shoulder_yaw_link.STL"/>
    <mesh name="left_elbow_link" file="left_elbow_link.STL"/>
    <mesh name="left_wrist_roll_link" file="left_wrist_roll_link.STL"/>
    <mesh name="right_shoulder_pitch_link" file="right_shoulder_pitch_link.STL"/>
    <mesh name="right_shoulder_roll_link" file="right_shoulder_roll_link.STL"/>
    <mesh name="right_shoulder_yaw_link" file="right_shoulder_yaw_link.STL"/>
    <mesh name="right_elbow_link" file="right_elbow_link.STL"/>
    <mesh name="right_wrist_roll_link" file="right_wrist_roll_link.STL"/>
    <mesh name="head_pitch_link" file="head_pitch_link.STL"/>
    <mesh name="head_yaw_link" file="head_yaw_link.STL"/>
  </asset>

  <worldbody>
    <body name="pelvis" pos="0 0 0.74" childclass="r1">
      <inertial pos="0.0269881 0.000184581 -0.0704106" quat="0.703476 0.707138 -0.0498219 0.0509351" mass="2.25001" diaginertia="0.00646721 0.00620017 0.00381749"/>
      <joint name="floating_base_joint" type="free" limited="false" actuatorfrclimited="false"/>
      <geom class="visual" rgba="0.79216 0.81961 0.93333 1" mesh="pelvis_link"/>
      <geom class="visual" pos="0.0762025 2.19914e-05 -0.0884315" quat="1 0 0 0" rgba="0.79216 0.81961 0.93333 1" mesh="imu_in_pelvis_link"/>
      <geom name="pelvis_collision" class="collision" type="sphere" size="0.05" pos="0.03 0 -0.08"/>
      <site name="imu" size="0.01" pos="0 0 0"/>
      <body name="left_hip_pitch_link" pos="0.0325 0.0704672 -0.0902351" quat="0.976296 -0.21644 0 0">
        <inertial pos="-0.003907 0.0415 -0.043716" quat="0.977607 0.186708 0.0209888 0.0947863" mass="0.935482" diaginertia="0.00105051 0.000997373 0.000565117"/>
        <joint name="left_hip_pitch_joint" pos="0 0 0" axis="0 1 0" range="-2.93215 2.54818"/>
        <geom class="visual" rgba="0.79216 0.81961 0.93333 1" mesh="left_hip_pitch_link"/>
        <body name="left_hip_roll_link" pos="0.0248 0.045 -0.053" quat="0.976296 0.21644 0 0">
          <inertial pos="-0.008002 -0.00206 -0.032798" quat="0.917982 -0.152984 0.363871 0.0387668" mass="0.207609" diaginertia="0.000298715 0.000236156 0.000181129"/>
          <joint name="left_hip_roll_joint" pos="0 0 0" axis="1 0 0" range="-1.0472 1.74533"/>
          <geom class="visual" rgba="0.79216 0.81961 0.93333 1" mesh="left_hip_roll_link"/>
          <geom name="left_hip_collision" class="collision" size="0.03" fromto="-0.025 0 0.025 -0.025 0 -0.025"/>
          <body name="left_hip_yaw_link" pos="-0.0194507 -0.0006 -0.0618">
            <inertial pos="-0.010059 -0.004848 -0.093609" quat="0.648721 0.0354742 0.0856084 0.755364" mass="1.73967" diaginertia="0.0083895 0.00828665 0.00127385"/>
            <joint name="left_hip_yaw_joint" pos="0 0 0" axis="0 0 1" range="-2.7402 2.7402"/>
            <geom class="visual" rgba="0.79216 0.81961 0.93333 1" mesh="left_hip_yaw_link"/>
            <geom name="left_thigh_collision" class="collision" size="0.03" fromto="0 0 -0.025 0 0 -0.125"/>
            <body name="left_knee_link" pos="-0.02315 0.01866 -0.159301">
              <inertial pos="-0.00946428 -0.0182147 -0.135746" quat="0.678998 -0.0104211 0.029549 0.733471" mass="2.37477" diaginertia="0.0128449 0.0125305 0.00195841"/>
              <joint name="left_knee_joint" pos="0 0 0" axis="0 1 0" range="-0.174533 2.42601"/>
              <geom class="visual" rgba="0.79216 0.81961 0.93333 1" mesh="left_knee_link"/>
              <geom name="left_shin_collision" class="collision" size="0.035" fromto="0.015 -0.02 -0.05 -0.01 -0.02 -0.2"/>
              <geom name="left_linkage_brace_collision" class="collision" size="0.015" fromto="-0.01 -0.02 -0.26 -0.015 -0.02 -0.32"/>
              <body name="left_ankle_pitch_link" pos="-0.0168139 -0.0205811 -0.309175">
                <inertial pos="-0.000104 0 -0.00772" quat="0.707107 0 0 0.707107" mass="0.071231" diaginertia="1.2e-05 7e-06 7e-06"/>
                <joint name="left_ankle_pitch_joint" pos="0 0 0" axis="0 1 0" range="-0.87266 0.57596"/>
                <geom class="visual" rgba="0.79216 0.81961 0.93333 1" mesh="left_ankle_pitch_link"/>
                <body name="left_ankle_roll_link">
                  <inertial pos="0.0296647 0 -0.0326975" quat="0 0.737468 0 0.675382" mass="0.481688" diaginertia="0.00126935 0.00121244 0.000230475"/>
                  <joint name="left_ankle_roll_joint" pos="0 0 0" axis="1 0 0" range="-0.2618 0.2618"/>
                  <geom class="visual" rgba="0.79216 0.81961 0.93333 1" mesh="left_ankle_roll_link"/>
                  <geom pos="0.021 0.014 -0.0094" quat="1 0 0 0" class="visual" rgba="1 0 0 1" mesh="left_ankle_constraint_A_link"/>
                  <geom pos="0.021 -0.014 -0.0094" quat="1 0 0 0" class="visual" rgba="0 0 1 1" mesh="left_ankle_constraint_B_link"/>
                  <geom name="left_foot1_collision" class="foot_capsule" fromto="0.05 -0.025 -0.045 0.1 -0.025 -0.045"/>
                  <geom name="left_foot2_collision" class="foot_capsule" fromto="-0.03 -0.02 -0.045 0.115 -0.02 -0.045"/>
                  <geom name="left_foot3_collision" class="foot_capsule" fromto="-0.038 -0.01 -0.045 0.12 -0.01 -0.045"/>
                  <geom name="left_foot4_collision" class="foot_capsule" fromto="-0.04 0 -0.045 0.123 0 -0.045"/>
                  <geom name="left_foot5_collision" class="foot_capsule" fromto="-0.038 0.01 -0.045 0.12 0.01 -0.045"/>
                  <geom name="left_foot6_collision" class="foot_capsule" fromto="-0.03 0.02 -0.045 0.115 0.02 -0.045"/>
                  <geom name="left_foot7_collision" class="foot_capsule" fromto="0.05 0.025 -0.045 0.1 0.025 -0.045"/>
                  <site name="left_foot" rgba="1 0 0 1" pos="0.04 0 -0.055"/>
                </body>
              </body>
            </body>
          </body>
        </body>
      </body>
      <body name="right_hip_pitch_link" pos="0.0325 -0.0704672 -0.0902351" quat="0.976296 0.21644 0 0">
        <inertial pos="-0.003907 -0.0415 -0.043716" quat="0.977607 -0.186708 0.0209888 -0.0947863" mass="0.935482" diaginertia="0.00105051 0.000997373 0.000565117"/>
        <joint name="right_hip_pitch_joint" pos="0 0 0" axis="0 1 0" range="-2.93215 2.54818"/>
        <geom class="visual" rgba="0.79216 0.81961 0.93333 1" mesh="right_hip_pitch_link"/>
        <body name="right_hip_roll_link" pos="0.0248 -0.045 -0.053" quat="0.976296 -0.21644 0 0">
          <inertial pos="-0.008002 0.00206 -0.032798" quat="0.917982 0.152984 0.363871 -0.0387668" mass="0.207609" diaginertia="0.000298715 0.000236156 0.000181129"/>
          <joint name="right_hip_roll_joint" pos="0 0 0" axis="1 0 0" range="-1.74533 1.0472"/>
          <geom class="visual" rgba="0.79216 0.81961 0.93333 1" mesh="right_hip_roll_link"/>
          <geom name="right_hip_collision" class="collision" size="0.03" fromto="-0.025 0 0.025 -0.025 0 -0.025"/>
          <body name="right_hip_yaw_link" pos="-0.0194507 0.0006 -0.0618">
            <inertial pos="-0.010059 0.004848 -0.093609" quat="0.755364 0.0856084 0.0354742 0.648721" mass="1.73967" diaginertia="0.0083895 0.00828665 0.00127385"/>
            <joint name="right_hip_yaw_joint" pos="0 0 0" axis="0 0 1" range="-2.7402 2.7402"/>
            <geom class="visual" rgba="0.79216 0.81961 0.93333 1" mesh="right_hip_yaw_link"/>
            <geom name="right_thigh_collision" class="collision" size="0.03" fromto="0 0 -0.025 0 0 -0.125"/>
            <body name="right_knee_link" pos="-0.02315 -0.01866 -0.159301">
              <inertial pos="-0.00946428 0.0182147 -0.135746" quat="0.733471 0.029549 -0.0104211 0.678998" mass="2.37477" diaginertia="0.0128449 0.0125305 0.00195841"/>
              <joint name="right_knee_joint" pos="0 0 0" axis="0 1 0" range="-0.17453 2.42601"/>
              <geom class="visual" rgba="0.79216 0.81961 0.93333 1" mesh="right_knee_link"/>
              <geom name="right_shin_collision" class="collision" size="0.035" fromto="0.015 0.02 -0.05 -0.01 0.02 -0.2"/>
              <geom name="right_linkage_brace_collision" class="collision" size="0.015" fromto="-0.01 0.02 -0.26 -0.015 0.02 -0.32"/>
              <body name="right_ankle_pitch_link" pos="-0.0168139 0.0205811 -0.309175">
                <inertial pos="-0.000104 0 -0.00772" quat="0.707107 0 0 0.707107" mass="0.071231" diaginertia="1.2e-05 7e-06 7e-06"/>
                <joint name="right_ankle_pitch_joint" pos="0 0 0" axis="0 1 0" range="-0.87266 0.57596"/>
                <geom class="visual" rgba="0.79216 0.81961 0.93333 1" mesh="right_ankle_pitch_link"/>
                <body name="right_ankle_roll_link">
                  <inertial pos="0.0296647 0 -0.0326975" quat="0 0.737468 0 0.675382" mass="0.481688" diaginertia="0.00126935 0.00121244 0.000230475"/>
                  <joint name="right_ankle_roll_joint" pos="0 0 0" axis="1 0 0" range="-0.261799 0.261799"/>
                  <geom class="visual" rgba="0.79216 0.81961 0.93333 1" mesh="right_ankle_roll_link"/>
                  <geom pos="0.021 -0.014 -0.0094" quat="1 0 0 0" class="visual" rgba="1 0 0 1" mesh="right_ankle_constraint_A_link"/>
                  <geom pos="0.021 0.014 -0.0094" quat="1 0 0 0" class="visual" rgba="0 0 1 1" mesh="right_ankle_constraint_B_link"/>
                  <geom name="right_foot1_collision" class="foot_capsule" fromto="0.05 -0.025 -0.045 0.1 -0.025 -0.045"/>
                  <geom name="right_foot2_collision" class="foot_capsule" fromto="-0.03 -0.02 -0.045 0.115 -0.02 -0.045"/>
                  <geom name="right_foot3_collision" class="foot_capsule" fromto="-0.038 -0.01 -0.045 0.12 -0.01 -0.045"/>
                  <geom name="right_foot4_collision" class="foot_capsule" fromto="-0.04 0 -0.045 0.123 0 -0.045"/>
                  <geom name="right_foot5_collision" class="foot_capsule" fromto="-0.038 0.01 -0.045 0.12 0.01 -0.045"/>
                  <geom name="right_foot6_collision" class="foot_capsule" fromto="-0.03 0.02 -0.045 0.115 0.02 -0.045"/>
                  <geom name="right_foot7_collision" class="foot_capsule" fromto="0.05 0.025 -0.045 0.1 0.025 -0.045"/>
                  <site name="right_foot" rgba="1 0 0 1" pos="0.04 0 -0.055"/>
                </body>
              </body>
            </body>
          </body>
        </body>
      </body>
      <body name="waist_roll_link">
        <inertial pos="0.030601 0 0.004788" quat="0.999992 0 -0.00390592 0" mass="0.920736" diaginertia="0.000806008 0.000734 0.000677992"/>
        <joint name="waist_roll_joint" pos="0 0 0" axis="1 0 0" range="-0.5236 0.5236"/>
        <geom pos="0.0325 0 0.049" class="visual" rgba="0.79216 0.81961 0.93333 1" mesh="waist_roll_link"/>
        <body name="torso_link" pos="0.0325 0 0.049">
          <inertial pos="0.000409289 -0.000333222 0.181216" quat="0.999992 -0.000325591 0.00182329 -0.00361781" mass="7.3387" diaginertia="0.110151 0.10028 0.0271256"/>
          <joint name="waist_yaw_joint" pos="0 0 0" axis="0 0 1" range="-2.618 2.618"/>
          <geom class="visual" rgba="0.79216 0.81961 0.93333 1" mesh="waist_yaw_link"/>
          <geom pos="-0.006 0.03155 0.255" class="visual" rgba="0.79216 0.81961 0.93333 1" mesh="head_pitch_link"/>
          <geom pos="-0.0049874 0 0.3715" quat="1 0 0 0" class="visual" rgba="0.79216 0.81961 0.93333 1" mesh="head_yaw_link"/>
          <geom name="torso_collision" class="collision" size="0.08" fromto="-0.02 0 0.1 -0.02 0 0.15"/>
          <geom name="head_collision" class="collision" type="sphere" size="0.055" pos="0.015 0 0.35"/>
          <body name="left_shoulder_pitch_link" pos="0 0.085688 0.19749" quat="0.99144 0.130561 0 0">
            <inertial pos="0.00294386 0.0447687 -0.0228687" quat="0.933514 0.315801 -0.107611 0.131308" mass="0.83795" diaginertia="0.000664554 0.000644431 0.000530845"/>
            <joint name="left_shoulder_pitch_joint" pos="0 0 0" axis="0 1 0" range="-3.1416 2.0944"/>
            <geom class="visual" rgba="0.79216 0.81961 0.93333 1" mesh="left_shoulder_pitch_link"/>
            <body name="left_shoulder_roll_link" pos="0.03445 0.047132 -0.025693" quat="0.99144 -0.130561 0 0">
              <inertial pos="-0.037828 0.003967 -0.066496" quat="0.704928 -0.0676661 -0.0976966 0.699252" mass="0.740212" diaginertia="0.00108994 0.000995148 0.000547915"/>
              <joint name="left_shoulder_roll_joint" pos="0 0 0" axis="1 0 0" range="-0.22689 2.4784"/>
              <geom class="visual" rgba="0.79216 0.81961 0.93333 1" mesh="left_shoulder_roll_link"/>
              <body name="left_shoulder_yaw_link" pos="-0.03445 0.0043 -0.10835">
                <inertial pos="0.013143 -0.004355 -0.072948" quat="0.944453 -0.083861 -0.114993 0.29623" mass="0.738441" diaginertia="0.000862551 0.000851784 0.000435665"/>
                <joint name="left_shoulder_yaw_joint" pos="0 0 0" axis="0 0 1" range="-1.9199 1.9199"/>
                <geom class="visual" rgba="0.79216 0.81961 0.93333 1" mesh="left_shoulder_yaw_link"/>
                <geom name="left_shoulder_yaw_collision" class="collision" size="0.03" fromto="0 0 -0.03 0 0 0.1"/>
                <body name="left_elbow_link" pos="0.016191 0.026461 -0.082858">
                  <inertial pos="0.072371 -0.024612 -0.011566" quat="0.590432 0.585258 0.4407 0.338595" mass="0.759419" diaginertia="0.000969031 0.000938046 0.000470923"/>
                  <joint name="left_elbow_joint" pos="0 0 0" axis="0 1 0" range="-0.97564 2.1852"/>
                  <geom class="visual" rgba="0.79216 0.81961 0.93333 1" mesh="left_elbow_link"/>
                  <geom name="left_elbow_collision" class="collision" size="0.03" fromto="0.015 -0.025 -0.01 0.085 -0.025 -0.01"/>
                  <body name="left_wrist_roll_link" pos="0.11218 -0.03002 -0.011702">
                    <inertial pos="0.068045 -0.001688 0.001392" quat="0.442664 0.566917 0.411512 0.559742" mass="0.324767" diaginertia="0.000717953 0.000704181 0.000156865"/>
                    <joint name="left_wrist_roll_joint" pos="0 0 0" axis="1 0 0" range="-1.9199 1.9199"/>
                    <geom class="visual" rgba="0.79216 0.81961 0.93333 1" mesh="left_wrist_roll_link"/>
                    <geom name="left_hand_collision" class="collision" size="0.03" rgba="0.2 0.6 0.2 0.2" fromto="0.05 0 0 0.12 0 0"/>
                    <site name="left_palm" pos="0.1 0 0" size="0.01"/>
                  </body>
                </body>
              </body>
            </body>
          </body>
          <body name="right_shoulder_pitch_link" pos="0 -0.085688 0.19749" quat="0.99144 -0.130561 0 0">
            <inertial pos="0.00294386 -0.0447687 -0.0228687" quat="0.933514 -0.315801 -0.107611 -0.131308" mass="0.83795" diaginertia="0.000664554 0.000644431 0.000530845"/>
            <joint name="right_shoulder_pitch_joint" pos="0 0 0" axis="0 1 0" range="-3.1416 2.0944"/>
            <geom class="visual" rgba="0.79216 0.81961 0.93333 1" mesh="right_shoulder_pitch_link"/>
            <body name="right_shoulder_roll_link" pos="0.03445 -0.047132 -0.025693" quat="0.99144 0.130561 0 0">
              <inertial pos="-0.037828 -0.003967 -0.066496" quat="0.699252 -0.0976966 -0.0676661 0.704928" mass="0.740212" diaginertia="0.00108994 0.000995148 0.000547915"/>
              <joint name="right_shoulder_roll_joint" pos="0 0 0" axis="1 0 0" range="-2.47849 0.2268"/>
              <geom class="visual" rgba="0.79216 0.81961 0.93333 1" mesh="right_shoulder_roll_link"/>
              <body name="right_shoulder_yaw_link" pos="-0.03445 -0.0043 -0.10835">
                <inertial pos="0.013143 0.004355 -0.072948" quat="0.944453 0.083861 -0.114993 -0.29623" mass="0.738441" diaginertia="0.000862551 0.000851784 0.000435665"/>
                <joint name="right_shoulder_yaw_joint" pos="0 0 0" axis="0 0 1" range="-1.9199 1.9199"/>
                <geom class="visual" rgba="0.79216 0.81961 0.93333 1" mesh="right_shoulder_yaw_link"/>
                <geom name="right_shoulder_yaw_collision" class="collision" size="0.03" fromto="0 0 -0.03 0 0 0.1"/>
                <body name="right_elbow_link" pos="0.016191 -0.026461 -0.082858">
                  <inertial pos="0.072371 0.024612 -0.011566" quat="0.338595 0.4407 0.585258 0.590432" mass="0.759419" diaginertia="0.000969031 0.000938046 0.000470923"/>
                  <joint name="right_elbow_joint" pos="0 0 0" axis="0 1 0" range="-0.97564 2.1852"/>
                  <geom class="visual" rgba="0.79216 0.81961 0.93333 1" mesh="right_elbow_link"/>
                  <geom name="right_elbow_collision" class="collision" size="0.03" fromto="0.015 0.025 -0.01 0.085 0.025 -0.01"/>
                  <body name="right_wrist_roll_link" pos="0.11218 0.03002 -0.011702">
                    <inertial pos="0.068045 0.001688 0.001392" quat="0.559742 0.411512 0.566917 0.442664" mass="0.324767" diaginertia="0.000717953 0.000704181 0.000156865"/>
                    <joint name="right_wrist_roll_joint" pos="0 0 0" axis="1 0 0" range="-1.9199 1.9199"/>
                    <geom class="visual" rgba="0.79216 0.81961 0.93333 1" mesh="right_wrist_roll_link"/>
                    <geom name="right_hand_collision" class="collision" size="0.03" rgba="0.2 0.6 0.2 0.2" fromto="0.05 0 0 0.12 0 0"/>
                    <site name="right_palm" pos="0.1 0 0" size="0.01"/>
                  </body>
                </body>
              </body>
            </body>
          </body>
        </body>
      </body>
    </body>
  </worldbody>
  <contact>
    <exclude body1="left_elbow_link" body2="left_wrist_pitch_link"/>
    <exclude body1="right_elbow_link" body2="right_wrist_pitch_link"/>
    <exclude body1="pelvis" body2="right_hip_roll_link"/>
    <exclude body1="pelvis" body2="left_hip_roll_link"/>
  </contact>
  <sensor>
    <gyro name="imu_ang_vel" site="imu"/>
    <velocimeter name="imu_lin_vel" site="imu"/>
    <accelerometer name="imu_lin_acc" site="imu"/>
    <subtreeangmom name="root_angmom" body="pelvis"/>
  </sensor>
</mujoco>
