<mujoco model="a2">
  <compiler angle="radian" meshdir="assets" autolimits="true" />

  <default>
    <default class="a2">
      <default class="visual">
        <geom type="mesh" contype="0" conaffinity="0" density="0" group="2"/>
      </default>
      <default class="collision">
        <geom priority="1" condim="6" group="3"/>
      </default>
      <site rgba="1 0 0 1" group="5"/>
    </default>
  </default>

  <asset>
    <mesh name="base_link" file="base_link.STL"/>
    <mesh name="left_front_Link1" file="left_front_Link1.STL"/>
    <mesh name="left_front_Link2" file="left_front_Link2.STL"/>
    <mesh name="left_front_Link3" file="left_front_Link3.STL"/>
    <mesh name="left_front_Link4" file="left_front_Link4.STL"/>
    <mesh name="left_hind_Link1" file="left_hind_Link1.STL"/>
    <mesh name="left_hind_Link2" file="left_hind_Link2.STL"/>
    <mesh name="left_hind_Link3" file="left_hind_Link3.STL"/>
    <mesh name="left_hind_Link4" file="left_hind_Link4.STL"/>
    <mesh name="right_front_Link1" file="right_front_Link1.STL"/>
    <mesh name="right_front_Link2" file="right_front_Link2.STL"/>
    <mesh name="right_front_Link3" file="right_front_Link3.STL"/>
    <mesh name="right_front_Link4" file="right_front_Link4.STL"/>
    <mesh name="right_hind_Link1" file="right_hind_Link1.STL"/>
    <mesh name="right_hind_Link2" file="right_hind_Link2.STL"/>
    <mesh name="right_hind_Link3" file="right_hind_Link3.STL"/>
    <mesh name="right_hind_Link4" file="right_hind_Link4.STL"/>
  </asset>

  <worldbody>
    <body name="base_link" pos="-1 1 0.6" childclass="a2">
      <inertial pos="0.00698259 -0.000712858 0.0128895" quat="-0.00152907 0.699583 -0.00252986 0.714546" mass="19.651" diaginertia="0.472398 0.407723 0.141627"/>
      <joint name="floating_base_joint" type="free" limited="false" actuatorfrclimited="false"/>
      <geom class="visual" rgba="0.792157 0.819608 0.933333 1" mesh="base_link"/>
      <geom name="base1_collision" class="collision" size="0.12 0.14 0.085" pos="0 0 0.007" type="box" rgba="0.792157 0.819608 0.933333 1"/>
      <geom name="base2_collision" class="collision" size="0.04 0.025 0.01" pos="0.25 0 0.119" type="box" rgba="0.792157 0.819608 0.933333 1"/>
      <geom name="base3_collision" class="collision" size="0.025 0.015 0.008" pos="-0.22 0 0.119" quat="0.999888 0 -0.0149994 0" type="box" rgba="0.792157 0.819608 0.933333 1"/>
      <geom name="base4_collision" class="collision" size="0.03 0.05 0.005" pos="0.365 0 0.1" quat="0.939373 0 -0.342898 0" type="box" rgba="0.792157 0.819608 0.933333 1"/>
      <geom name="base5_collision" class="collision" size="0.0225 0.05 0.005" pos="-0.31 0 0.112" quat="0.939373 0 0.342898 0" type="box" rgba="0.792157 0.819608 0.933333 1"/>
      <site name="imu" pos="0 0 0" />
      <body name="FL_hip" pos="0.25944 0.075113 0">
        <inertial pos="-0.002408 -0.01622 0.000239" quat="0.66751 0.421649 0.565191 0.239168" mass="1.62" diaginertia="0.0016644 0.00161602 0.00145995"/>
        <joint name="FL_hip_joint" pos="0 0 0" axis="1 0 0" range="-1.01 1.01"/>
        <geom class="visual" rgba="0.898039 0.917647 0.929412 1" mesh="left_front_Link1"/>
        <body name="FL_thigh" pos="0 0.12779 0">
          <inertial pos="-0.003268 -0.03111 -0.053896" quat="0.993045 0.11348 0.0231928 0.0211279" mass="3.079" diaginertia="0.0293395 0.0280448 0.00383794"/>
          <joint name="FL_thigh_joint" pos="0 0 0" axis="0 1 0" range="-2.34 3.15"/>
          <geom class="visual" rgba="0.898039 0.917647 0.929412 1" mesh="left_front_Link2"/>
          <geom name="FL_thigh1_collision" class="collision" size="0.048 0.06" pos="0 -0.04 0" quat="0.707035 0.707179 0 0" type="cylinder" rgba="0.898039 0.917647 0.929412 1"/>
          <geom name="FL_thigh2_collision" class="collision" size="0.0275 0.018 0.085" pos="-0.025 0 -0.09" quat="0.999988 0 0.00499998 0" type="box" rgba="0.898039 0.917647 0.929412 1"/>
          <geom name="FL_thigh3_collision" class="collision" size="0.0085 0.025 0.025" pos="-0.022 0 -0.27" quat="0.930508 0 -0.366273 0" type="box" rgba="0.898039 0.917647 0.929412 1"/>
          <body name="FL_calf" pos="0 0 -0.275">
            <inertial pos="0.0102138 -1.99312e-05 -0.136496" quat="0.706884 -0.0119077 -0.0120568 0.707127" mass="0.407" diaginertia="0.00511119 0.00502314 0.000177746"/>
            <joint name="FL_calf_joint" pos="0 0 0" axis="0 1 0" range="-2.77 -0.54"/>
            <geom class="visual" rgba="0.898039 0.917647 0.929412 1" mesh="left_front_Link3"/>
            <geom name="FL_calf1_collision" class="collision" size="0.012 0.015 0.05" pos="0.018 0 -0.08" quat="0.992809 0 -0.119712 0" type="box" rgba="0.898039 0.917647 0.929412 1"/>
            <geom name="FL_calf2_collision" class="collision" size="0.011 0.015 0.04" pos="0.033 0 -0.17" quat="0.999888 0 -0.0149994 0" type="box" rgba="0.898039 0.917647 0.929412 1"/>
            <geom name="FL_calf3_collision" class="collision" size="0.01 0.018 0.03" pos="0.029 0 -0.236" quat="0.995004 0 0.0998334 0" type="box" rgba="0.898039 0.917647 0.929412 1"/>
            <geom name="FL_calf4_collision" class="collision" size="0.005 0.018 0.03" pos="0.008 0 -0.23" quat="0.942755 0 0.333487 0" type="box" rgba="0.898039 0.917647 0.929412 1"/>
            <geom pos="0 0 -0.275" quat="1 0 0 0" class="visual" rgba="0.698039 0.698039 0.698039 1" mesh="left_front_Link4"/>
            <geom name="FL_foot_collision" class="collision" type="sphere" size="0.032" pos="0 0 -0.275" rgba="0.698039 0.698039 0.698039 1"/>
            <site name="FL" pos="0 0 -0.275" type="sphere" size="0.032"/>
          </body>
        </body>
      </body>
      <body name="FR_hip" pos="0.25944 -0.075113 0">
        <inertial pos="-0.002465 0.01622 0.000318" quat="0.244263 0.553086 0.449878 0.657299" mass="1.62" diaginertia="0.0016672 0.00160755 0.00146457"/>
        <joint name="FR_hip_joint" pos="0 0 0" axis="1 0 0" range="-1.01 1.01"/>
        <geom class="visual" rgba="0.898039 0.917647 0.929412 1" mesh="right_front_Link1"/>
        <body name="FR_thigh" pos="0 -0.12779 0">
          <inertial pos="-0.003256 0.031125 -0.053921" quat="0.993054 -0.113587 0.0234158 -0.0198545" mass="3.077" diaginertia="0.029323 0.028038 0.00383842"/>
          <joint name="FR_thigh_joint" pos="0 0 0" axis="0 1 0" range="-2.34 3.15"/>
          <geom class="visual" rgba="0.898039 0.917647 0.929412 1" mesh="right_front_Link2"/>
          <geom name="FR_thigh1_collision" class="collision" size="0.048 0.06" pos="0 0.04 0" quat="0.707035 0.707179 0 0" type="cylinder" rgba="0.898039 0.917647 0.929412 1"/>
          <geom name="FR_thigh2_collision" class="collision" size="0.0275 0.018 0.085" pos="-0.025 0 -0.09" quat="0.999988 0 0.00499998 0" type="box" rgba="0.898039 0.917647 0.929412 1"/>
          <geom name="FR_thigh3_collision" class="collision" size="0.0085 0.025 0.025" pos="-0.022 0 -0.27" quat="0.930508 0 -0.366273 0" type="box" rgba="0.898039 0.917647 0.929412 1"/>
          <body name="FR_calf" pos="0 0 -0.275">
            <inertial pos="0.0102138 1.55479e-05 -0.136496" quat="0.707151 -0.0120743 -0.0118903 0.706859" mass="0.407" diaginertia="0.00511119 0.00502314 0.000177746"/>
            <joint name="FR_calf_joint" pos="0 0 0" axis="0 1 0" range="-2.77 -0.54"/>
            <geom class="visual" rgba="0.898039 0.917647 0.929412 1" mesh="right_front_Link3"/>
            <geom name="FR_calf1_collision" class="collision" size="0.012 0.015 0.05" pos="0.018 0 -0.08" quat="0.992809 0 -0.119712 0" type="box" rgba="0.898039 0.917647 0.929412 1"/>
            <geom name="FR_calf2_collision" class="collision" size="0.011 0.015 0.04" pos="0.033 0 -0.17" quat="0.999888 0 -0.0149994 0" type="box" rgba="0.898039 0.917647 0.929412 1"/>
            <geom name="FR_calf3_collision" class="collision" size="0.01 0.018 0.03" pos="0.029 0 -0.236" quat="0.995004 0 0.0998334 0" type="box" rgba="0.898039 0.917647 0.929412 1"/>
            <geom name="FR_calf4_collision" class="collision" size="0.005 0.018 0.03" pos="0.008 0 -0.23" quat="0.942755 0 0.333487 0" type="box" rgba="0.898039 0.917647 0.929412 1"/>
            <geom pos="0 0 -0.275" quat="1 0 0 0" class="visual" rgba="0.698039 0.698039 0.698039 1" mesh="right_front_Link4"/>
            <geom name="FR_foot_collision" class="collision" type="sphere" size="0.032" pos="0 0 -0.275" rgba="0.698039 0.698039 0.698039 1"/>
            <site name="FR" pos="0 0 -0.275" type="sphere" size="0.032"/>
          </body>
        </body>
      </body>
      <body name="RL_hip" pos="-0.25944 0.075113 0">
        <inertial pos="0.00327 -0.01622 -9.7e-05" quat="0.358494 0.383537 0.580824 0.622113" mass="1.62" diaginertia="0.00167848 0.00163116 0.00141504"/>
        <joint name="RL_hip_joint" pos="0 0 0" axis="1 0 0" range="-1.01 1.01"/>
        <geom class="visual" rgba="0.898039 0.917647 0.929412 1" mesh="left_hind_Link1"/>
        <body name="RL_thigh" pos="0 0.12779 0">
          <inertial pos="-0.003268 -0.03111 -0.053896" quat="0.993045 0.11348 0.0231928 0.0211279" mass="3.079" diaginertia="0.0293395 0.0280448 0.00383794"/>
          <joint name="RL_thigh_joint" pos="0 0 0" axis="0 1 0" range="-1.56 3.94"/>
          <geom class="visual" rgba="0.898039 0.917647 0.929412 1" mesh="left_hind_Link2"/>
          <geom name="RL_thigh1_collision" class="collision" size="0.048 0.06" pos="0 -0.04 0" quat="0.707035 0.707179 0 0" type="cylinder" rgba="0.898039 0.917647 0.929412 1"/>
          <geom name="RL_thigh2_collision" class="collision" size="0.0275 0.018 0.085" pos="-0.025 0 -0.09" quat="0.999988 0 0.00499998 0" type="box" rgba="0.898039 0.917647 0.929412 1"/>
          <geom name="RL_thigh3_collision" class="collision" size="0.0085 0.025 0.025" pos="-0.022 0 -0.27" quat="0.930508 0 -0.366273 0" type="box" rgba="0.898039 0.917647 0.929412 1"/>
          <body name="RL_calf" pos="0 0 -0.275">
            <inertial pos="0.0102138 -1.99312e-05 -0.136496" quat="0.706884 -0.0119077 -0.0120568 0.707127" mass="0.407" diaginertia="0.00511119 0.00502314 0.000177746"/>
            <joint name="RL_calf_joint" pos="0 0 0" axis="0 1 0" range="-2.77 -0.54"/>
            <geom class="visual" rgba="0.898039 0.917647 0.929412 1" mesh="left_hind_Link3"/>
            <geom name="RL_calf1_collision" class="collision" size="0.012 0.015 0.05" pos="0.018 0 -0.08" quat="0.992809 0 -0.119712 0" type="box" rgba="0.898039 0.917647 0.929412 1"/>
            <geom name="RL_calf2_collision" class="collision" size="0.011 0.015 0.04" pos="0.033 0 -0.17" quat="0.999888 0 -0.0149994 0" type="box" rgba="0.898039 0.917647 0.929412 1"/>
            <geom name="RL_calf3_collision" class="collision" size="0.01 0.018 0.03" pos="0.029 0 -0.236" quat="0.995004 0 0.0998334 0" type="box" rgba="0.898039 0.917647 0.929412 1"/>
            <geom name="RL_calf4_collision" class="collision" size="0.005 0.018 0.03" pos="0.008 0 -0.23" quat="0.942755 0 0.333487 0" type="box" rgba="0.898039 0.917647 0.929412 1"/>
            <geom pos="0 0 -0.275" quat="1 0 0 0" class="visual" rgba="0.698039 0.698039 0.698039 1" mesh="left_hind_Link4"/>
            <geom name="RL_foot_collision" class="collision" type="sphere" size="0.032" pos="0 0 -0.275" rgba="0.698039 0.698039 0.698039 1"/>
            <site name="RL" pos="0 0 -0.275" type="sphere" size="0.032"/>
          </body>
        </body>
      </body>
      <body name="RR_hip" pos="-0.25944 -0.075113 0">
        <inertial pos="0.00327 0.01622 -3.7e-05" quat="0.616206 0.585144 0.36648 0.378931" mass="1.62" diaginertia="0.00167769 0.00163476 0.00141225"/>
        <joint name="RR_hip_joint" pos="0 0 0" axis="1 0 0" range="-1.01 1.01"/>
        <geom class="visual" rgba="0.898039 0.917647 0.929412 1" mesh="right_hind_Link1"/>
        <body name="RR_thigh" pos="0 -0.12779 0">
          <inertial pos="-0.003256 0.031125 -0.053921" quat="0.993054 -0.113587 0.0234158 -0.0198545" mass="3.077" diaginertia="0.029323 0.028038 0.00383842"/>
          <joint name="RR_thigh_joint" pos="0 0 0" axis="0 1 0" range="-1.56 3.94"/>
          <geom class="visual" rgba="0.898039 0.917647 0.929412 1" mesh="right_hind_Link2"/>
          <geom name="RR_thigh1_collision" class="collision" size="0.048 0.06" pos="0 0.04 0" quat="0.707035 0.707179 0 0" type="cylinder" rgba="0.898039 0.917647 0.929412 1"/>
          <geom name="RR_thigh2_collision" class="collision" size="0.0275 0.018 0.085" pos="-0.025 0 -0.09" quat="0.999988 0 0.00499998 0" type="box" rgba="0.898039 0.917647 0.929412 1"/>
          <geom name="RR_thigh3_collision" class="collision" size="0.0085 0.025 0.025" pos="-0.022 0 -0.27" quat="0.930508 0 -0.366273 0" type="box" rgba="0.898039 0.917647 0.929412 1"/>
          <body name="RR_calf" pos="0 0 -0.275">
            <inertial pos="0.0102138 1.55479e-05 -0.136496" quat="0.707151 -0.0120743 -0.0118903 0.706859" mass="0.407" diaginertia="0.00511119 0.00502314 0.000177746"/>
            <joint name="RR_calf_joint" pos="0 0 0" axis="0 1 0" range="-2.77 -0.54"/>
            <geom class="visual" rgba="0.898039 0.917647 0.929412 1" mesh="right_hind_Link3"/>
            <geom name="RR_calf1_collision" class="collision" size="0.012 0.015 0.05" pos="0.018 0 -0.08" quat="0.992809 0 -0.119712 0" type="box" rgba="0.898039 0.917647 0.929412 1"/>
            <geom name="RR_calf2_collision" class="collision" size="0.011 0.015 0.04" pos="0.033 0 -0.17" quat="0.999888 0 -0.0149994 0" type="box" rgba="0.898039 0.917647 0.929412 1"/>
            <geom name="RR_calf3_collision" class="collision" size="0.01 0.018 0.03" pos="0.029 0 -0.236" quat="0.995004 0 0.0998334 0" type="box" rgba="0.898039 0.917647 0.929412 1"/>
            <geom name="RR_calf4_collision" class="collision" size="0.005 0.018 0.03" pos="0.008 0 -0.23" quat="0.942755 0 0.333487 0" type="box" rgba="0.898039 0.917647 0.929412 1"/>
            <geom pos="0 0 -0.275" quat="1 0 0 0" class="visual" rgba="0.698039 0.698039 0.698039 1" mesh="right_hind_Link4"/>
            <geom name="RR_foot_collision" class="collision" type="sphere" size="0.032" pos="0 0 -0.275" rgba="0.698039 0.698039 0.698039 1"/>
            <site name="RR" pos="0 0 -0.275" type="sphere" size="0.032"/>
          </body>
        </body>
      </body>
    </body>
  </worldbody>
  <sensor>
    <gyro name="imu_ang_vel" site="imu"/>
    <velocimeter name="imu_lin_vel" site="imu"/>
    <accelerometer name="imu_lin_acc" site="imu"/>
    <subtreeangmom name="root_angmom" body="base_link"/>
  </sensor>
</mujoco>
