<mujoco model="as2">
  <compiler angle="radian" meshdir="assets" autolimits="true" />

  <default>
    <default class="as2">
      <default class="visual">
        <geom type="mesh" contype="0" conaffinity="0" density="0" group="2"/>
      </default>
      <default class="collision">
        <geom priority="1" condim="6" group="3"/>
      </default>
      <site rgba="1 0 0 1" group="5"/>
    </default>
  </default>

  <asset>
    <mesh name="base_link" file="base_link.STL" />
    <mesh name="FL_hip" file="FL_hip.STL" />
    <mesh name="FL_thigh" file="FL_thigh.STL" />
    <mesh name="FL_calf" file="FL_calf.STL" />
    <mesh name="FL_foot" file="FL_foot.STL" />
    <mesh name="FR_hip" file="FR_hip.STL" />
    <mesh name="FR_thigh" file="FR_thigh.STL" />
    <mesh name="FR_calf" file="FR_calf.STL" />
    <mesh name="FR_foot" file="FR_foot.STL" />
    <mesh name="RL_hip" file="RL_hip.STL" />
    <mesh name="RL_thigh" file="RL_thigh.STL" />
    <mesh name="RL_calf" file="RL_calf.STL" />
    <mesh name="RL_foot" file="RL_foot.STL" />
    <mesh name="RR_hip" file="RR_hip.STL" />
    <mesh name="RR_thigh" file="RR_thigh.STL" />
    <mesh name="RR_calf" file="RR_calf.STL" />
    <mesh name="RR_foot" file="RR_foot.STL" />
  </asset>

  <worldbody>
    <body name="base_link" pos="0 0 0.5" childclass="as2">
      <inertial pos="0.0071793 0.0034909 0.0010238" quat="0.00267058 0.668402 -0.00393659 0.743785" mass="8.8" diaginertia="0.0855362 0.0623218 0.0390086" />
      <joint name="floating_base_joint" type="free" limited="false" actuatorfrclimited="false" />
      <geom class="visual" rgba="0.79216 0.81961 0.93333 1" mesh="base_link" />
      <geom name="base1_collision" class="collision" size="0.1 0.112 0.067" type="box" rgba="0.79216 0.81961 0.93333 1"/>
      <geom name="base2_collision" class="collision" size="0.043" pos="0.275 0 0.075" rgba="0.79216 0.81961 0.93333 1"/>
      <geom name="base3_collision" class="collision" size="0.045 0.03" pos="0.23 0 0.082" quat="0.640997 0 0.767544 0" type="cylinder" rgba="0.79216 0.81961 0.93333 1"/>
      <site name="imu" pos="0 0 0" />
      <body name="FL_hip" pos="0.2079 0.06 0">
        <inertial pos="-0.0032695 -0.0084443 -6.7598e-06" quat="0.553561 0.552726 0.441185 0.439796" mass="0.695" diaginertia="0.000535089 0.00047834 0.000414001"/>
        <joint name="FL_hip_joint" pos="0 0 0" axis="1 0 0" range="-0.785 0.785"/>
        <geom class="visual" quat="2.67949e-08 0 1 0" rgba="0.79216 0.81961 0.93333 1" mesh="FL_hip"/>
        <body name="FL_thigh" pos="0 0.1044 0">
          <inertial pos="-0.0039851 -0.030667 -0.025688" quat="0.986045 0.135475 0.0457974 0.0852343" mass="1.25" diaginertia="0.00502905 0.00486158 0.00101828"/>
          <joint name="FL_thigh_joint" pos="0 0 0" axis="0 1 0" range="-2 3.492"/>
          <geom class="visual" rgba="0.79216 0.81961 0.93333 1" mesh="FL_thigh"/>
          <geom name="FL_thigh1_collision" class="collision" size="0.04 0.05" pos="0 -0.03 0" quat="0.707035 0.707179 0 0" type="cylinder" rgba="0.79216 0.81961 0.93333 1"/>
          <geom name="FL_thigh2_collision" class="collision" size="0.0225 0.015 0.07" pos="-0.02 0 -0.09" quat="0.99875 0 0.0499792 0" type="box" rgba="0.79216 0.81961 0.93333 1"/>
          <geom name="FL_thigh3_collision" class="collision" size="0.005 0.0175 0.02" pos="-0.02 0 -0.21" quat="0.926798 0 -0.375559 0" type="box" rgba="0.79216 0.81961 0.93333 1"/>
          <body name="FL_calf" pos="0 0 -0.212">
            <inertial pos="0.00627259 5.00721e-05 -0.116603" quat="0.707251 -0.0112156 -0.0113283 0.706783" mass="0.265" diaginertia="0.00188217 0.00184859 6.92432e-05"/>
            <joint name="FL_calf_joint" pos="0 0 0" axis="0 1 0" range="-2.7677 -0.8133"/>
            <geom class="visual" rgba="0.79216 0.81961 0.93333 1" mesh="FL_calf" />
            <geom name="FL_calf1_collision" class="collision" size="0.016 0.025" pos="0.01 0 -0.08" quat="0.991562 0 -0.129634 0" type="cylinder" rgba="0.79216 0.81961 0.93333 1"/>
            <geom name="FL_calf2_collision" class="collision" size="0.012 0.03" pos="0.023 0 -0.13" quat="0.99875 0 -0.0499792 0" type="cylinder" rgba="0.79216 0.81961 0.93333 1"/>
            <geom name="FL_calf3_collision" class="collision" size="0.012 0.0275" pos="0.022 0 -0.185" quat="0.997189 0 0.0749297 0" type="cylinder" rgba="0.79216 0.81961 0.93333 1"/>
            <geom class="visual" pos="0 0 -0.21348" quat="1 0 0 0" rgba="0.79216 0.81961 0.93333 1" mesh="FL_foot" />
            <geom name="FL_foot_collision" class="collision" type="sphere" size="0.026" pos="0 0 -0.21348" rgba="0.698039 0.698039 0.698039 1"/>
            <site name="FL" pos="0 0 -0.21348" type="sphere" size="0.026"/>
          </body>
        </body>
      </body>
      <body name="FR_hip" pos="0.2079 -0.06 0">
        <inertial pos="-0.0032696 0.0084442 -6.762e-06" quat="0.439796 0.441185 0.552726 0.553561" mass="0.695" diaginertia="0.000535089 0.00047834 0.000414001" />
        <joint name="FR_hip_joint" pos="0 0 0" axis="1 0 0" range="-0.785 0.785"/>
        <geom class="visual" rgba="0.79216 0.81961 0.93333 1" mesh="FR_hip" />
        <body name="FR_thigh" pos="0 -0.1044 0">
          <inertial pos="-0.0039864 0.030665 -0.025694" quat="0.986054 -0.13545 0.0458057 -0.0851622" mass="1.25" diaginertia="0.00503005 0.00486245 0.0010183" />
          <joint name="FR_thigh_joint" pos="0 0 0" axis="0 1 0" range="-2 3.492"/>
          <geom class="visual" rgba="0.79216 0.81961 0.93333 1" mesh="FR_thigh" />
          <geom name="FR_thigh1_collision" class="collision" size="0.04 0.05" pos="0 0.03 0" quat="0.707035 0.707179 0 0" type="cylinder" rgba="0.79216 0.81961 0.93333 1"/>
          <geom name="FR_thigh2_collision" class="collision" size="0.0225 0.015 0.07" pos="-0.02 0 -0.09" quat="0.99875 0 0.0499792 0" type="box" rgba="0.79216 0.81961 0.93333 1"/>
          <geom name="FR_thigh3_collision" class="collision" size="0.005 0.0175 0.02" pos="-0.02 0 -0.21" quat="0.926798 0 -0.375559 0" type="box" rgba="0.79216 0.81961 0.93333 1"/>
          <body name="FR_calf" pos="0 0 -0.212">
            <inertial pos="0.00621508 -6.48265e-05 -0.116143" quat="0.707354 -0.0114039 -0.0112421 0.706678" mass="0.265" diaginertia="0.00189025 0.00185663 7.2022e-05" />
            <joint name="FR_calf_joint" pos="0 0 0" axis="0 1 0" range="-2.7677 -0.8133"/>
            <geom class="visual" rgba="0.79216 0.81961 0.93333 1" mesh="FR_calf" />
            <geom name="FR_calf1_collision" class="collision" size="0.016 0.025" pos="0.01 0 -0.08" quat="0.991562 0 -0.129634 0" type="cylinder" rgba="0.79216 0.81961 0.93333 1"/>
            <geom name="FR_calf2_collision" class="collision" size="0.012 0.03" pos="0.023 0 -0.13" quat="0.99875 0 -0.0499792 0" type="cylinder" rgba="0.79216 0.81961 0.93333 1"/>
            <geom name="FR_calf3_collision" class="collision" size="0.012 0.0275" pos="0.022 0 -0.185" quat="0.997189 0 0.0749297 0" type="cylinder" rgba="0.79216 0.81961 0.93333 1"/>
            <geom class="visual" pos="0 0 -0.21348" quat="1 0 0 0" rgba="0.79216 0.81961 0.93333 1" mesh="FR_foot" />
            <geom name="FR_foot_collision" class="collision" type="sphere" size="0.026" pos="0 0 -0.21348" rgba="0.698039 0.698039 0.698039 1"/>
            <site name="FR" pos="0 0 -0.21348" type="sphere" size="0.026"/>
          </body>
        </body>
      </body>
      <body name="RL_hip" pos="-0.2079 0.06 0">
        <inertial pos="0.0032918 -0.0084443 6.7725e-06" quat="0.43943 0.440822 0.553019 0.553848" mass="0.695" diaginertia="0.000534269 0.00047749 0.000413972" />
        <joint name="RL_hip_joint" pos="0 0 0" axis="1 0 0" range="-0.785 0.785"/>
        <geom class="visual" rgba="0.79216 0.81961 0.93333 1" mesh="RL_hip" />
        <body name="RL_thigh" pos="0 0.1044 0">
          <inertial pos="-0.0039851 -0.030667 -0.025688" quat="0.986045 0.135475 0.0457974 0.0852343" mass="1.25" diaginertia="0.00502905 0.00486158 0.00101828" />
          <joint name="RL_thigh_joint" pos="0 0 0" axis="0 1 0" range="-1.3 4.19"/>
          <geom class="visual" rgba="0.79216 0.81961 0.93333 1" mesh="RL_thigh" />
          <geom name="RL_thigh1_collision" class="collision" size="0.04 0.05" pos="0 -0.03 0" quat="0.707035 0.707179 0 0" type="cylinder" rgba="0.79216 0.81961 0.93333 1"/>
          <geom name="RL_thigh2_collision" class="collision" size="0.0225 0.015 0.07" pos="-0.02 0 -0.09" quat="0.99875 0 0.0499792 0" type="box" rgba="0.79216 0.81961 0.93333 1"/>
          <geom name="RL_thigh3_collision" class="collision" size="0.005 0.0175 0.02" pos="-0.02 0 -0.21" quat="0.926798 0 -0.375559 0" type="box" rgba="0.79216 0.81961 0.93333 1"/>
          <body name="RL_calf" pos="0 0 -0.212">
            <inertial pos="0.00627259 5.00797e-05 -0.116603" quat="0.707251 -0.0112155 -0.0113283 0.706783" mass="0.265" diaginertia="0.00188217 0.00184859 6.92432e-05" />
            <joint name="RL_calf_joint" pos="0 0 0" axis="0 1 0" range="-2.7677 -0.8133"/>
            <geom class="visual" rgba="0.79216 0.81961 0.93333 1" mesh="RL_calf" />
            <geom name="RL_calf1_collision" class="collision" size="0.016 0.025" pos="0.01 0 -0.08" quat="0.991562 0 -0.129634 0" type="cylinder" rgba="0.79216 0.81961 0.93333 1"/>
            <geom name="RL_calf2_collision" class="collision" size="0.012 0.03" pos="0.023 0 -0.13" quat="0.99875 0 -0.0499792 0" type="cylinder" rgba="0.79216 0.81961 0.93333 1"/>
            <geom name="RL_calf3_collision" class="collision" size="0.012 0.0275" pos="0.022 0 -0.185" quat="0.997189 0 0.0749297 0" type="cylinder" rgba="0.79216 0.81961 0.93333 1"/>
            <geom class="visual" pos="0 0 -0.21348" quat="1 0 0 0" rgba="0.79216 0.81961 0.93333 1" mesh="RL_foot" />
            <geom name="RL_foot_collision" class="collision" type="sphere" size="0.026" pos="0 0 -0.21348" rgba="0.698039 0.698039 0.698039 1"/>
            <site name="RL" pos="0 0 -0.21348" type="sphere" size="0.026"/>
          </body>
        </body>
      </body>
      <body name="RR_hip" pos="-0.2079 -0.06 0">
        <inertial pos="0.0032919 0.0084442 6.7701e-06" quat="0.553848 0.553019 0.440822 0.43943" mass="0.695" diaginertia="0.000534269 0.00047749 0.000413972" />
        <joint name="RR_hip_joint" pos="0 0 0" axis="1 0 0" range="-0.785 0.785"/>
        <geom class="visual" rgba="0.79216 0.81961 0.93333 1" mesh="RR_hip" />
        <body name="RR_thigh" pos="0 -0.1044 0">
          <inertial pos="-0.0039864 0.030665 -0.025694" quat="0.986054 -0.13545 0.0458057 -0.0851622" mass="1.25" diaginertia="0.00503005 0.00486245 0.0010183" />
          <joint name="RR_thigh_joint" pos="0 0 0" axis="0 1 0" range="-1.3 4.19"/>
          <geom class="visual" rgba="0.79216 0.81961 0.93333 1" mesh="RR_thigh" />
          <geom name="RR_thigh1_collision" class="collision" size="0.04 0.05" pos="0 0.03 0" quat="0.707035 0.707179 0 0" type="cylinder" rgba="0.79216 0.81961 0.93333 1"/>
          <geom name="RR_thigh2_collision" class="collision" size="0.0225 0.015 0.07" pos="-0.02 0 -0.09" quat="0.99875 0 0.0499792 0" type="box" rgba="0.79216 0.81961 0.93333 1"/>
          <geom name="RR_thigh3_collision" class="collision"size="0.005 0.0175 0.02" pos="-0.02 0 -0.21" quat="0.926798 0 -0.375559 0" type="box" rgba="0.79216 0.81961 0.93333 1"/>
          <body name="RR_calf" pos="0 0 -0.212">
            <inertial pos="0.00621508 -6.48255e-05 -0.116143" quat="0.707354 -0.0114039 -0.0112421 0.706678" mass="0.265" diaginertia="0.00189025 0.00185663 7.2022e-05" />
            <joint name="RR_calf_joint" pos="0 0 0" axis="0 1 0" range="-2.7677 -0.8133"/>
            <geom class="visual" rgba="0.79216 0.81961 0.93333 1" mesh="RR_calf" />
            <geom name="RR_calf1_collision" class="collision" size="0.016 0.025" pos="0.01 0 -0.08" quat="0.991562 0 -0.129634 0" type="cylinder" rgba="0.79216 0.81961 0.93333 1"/>
            <geom name="RR_calf2_collision" class="collision" size="0.012 0.03" pos="0.023 0 -0.13" quat="0.99875 0 -0.0499792 0" type="cylinder" rgba="0.79216 0.81961 0.93333 1"/>
            <geom name="RR_calf3_collision" class="collision"size="0.012 0.0275" pos="0.022 0 -0.185" quat="0.997189 0 0.0749297 0" type="cylinder" rgba="0.79216 0.81961 0.93333 1"/>
            <geom class="visual" pos="0 0 -0.21348" quat="1 0 0 0" rgba="0.79216 0.81961 0.93333 1" mesh="RR_foot" />
            <geom name="RR_foot_collision" class="collision" type="sphere" size="0.026" pos="0 0 -0.21348" rgba="0.698039 0.698039 0.698039 1"/>
            <site name="RR" pos="0 0 -0.21348" type="sphere" size="0.026"/>
          </body>
        </body>
      </body>
    </body>
  </worldbody>
  <sensor>
    <gyro name="imu_ang_vel" site="imu"/>
    <velocimeter name="imu_lin_vel" site="imu"/>
    <accelerometer name="imu_lin_acc" site="imu"/>
    <subtreeangmom name="root_angmom" body="base_link"/>
  </sensor>
</mujoco>
