<?xml version="1.0" encoding="utf-8"?>
<mujoco model="zgwt">
  <compiler angle="radian" meshdir="assets" autolimits="true"/>
  <option cone="elliptic" impratio="100" timestep="0.005"/>
  <default>
    <default class="zgwt">
      <geom friction="0.8 0.02 0.01" margin="0.001" condim="3"/>
      <joint damping="0.1" armature="0.01" frictionloss="0.2"/>
      <motor ctrlrange="-35.55 35.55"/>
      <default class="visual">
        <geom type="mesh" contype="0" conaffinity="0" group="2" mass="0"/>
      </default>
      <default class="collision">
        <geom group="3"/>
      </default>
    </default>
  </default>
  <asset>
    <material name="body_gray" rgba="0.75 0.75 0.75 1"/>
    <material name="dark" rgba="0.30 0.30 0.30 1"/>
    <material name="cream" rgba="1.00 0.95 0.90 1"/>
    <mesh name="BASE_LINK_0" file="BASE_LINK_0.STL"/>
    <mesh name="BASE_LINK_1" file="BASE_LINK_1.STL"/>
    <mesh name="BASE_LINK_2" file="BASE_LINK_2.STL"/>
    <mesh name="BASE_LINK_3" file="BASE_LINK_3.STL"/>
    <mesh name="BASE_LINK_4" file="BASE_LINK_4.STL"/>
    <mesh name="BASE_LINK_5" file="BASE_LINK_5.STL"/>
    <mesh name="BASE_LINK_6" file="BASE_LINK_6.STL"/>
    <mesh name="BASE_LINK_7" file="BASE_LINK_7.STL"/>
    <mesh name="FAR_ABAD_LINK" file="FAR_ABAD_LINK.STL"/>
    <mesh name="FAR_HIP_LINK" file="FAR_HIP_LINK.STL"/>
    <mesh name="FAR_KNEE_LINK" file="FAR_KNEE_LINK.STL"/>
    <mesh name="FAR_FOOT_LINK" file="FAR_FOOT_LINK.STL"/>
    <mesh name="FBL_ABAD_LINK" file="FBL_ABAD_LINK.STL"/>
    <mesh name="FBL_HIP_LINK" file="FBL_HIP_LINK.STL"/>
    <mesh name="FBL_KNEE_LINK" file="FBL_KNEE_LINK.STL"/>
    <mesh name="FBL_FOOT_LINK" file="FBL_FOOT_LINK.STL"/>
    <mesh name="RAR_ABAD_LINK" file="RAR_ABAD_LINK.STL"/>
    <mesh name="RAR_HIP_LINK" file="RAR_HIP_LINK.STL"/>
    <mesh name="RAR_KNEE_LINK" file="RAR_KNEE_LINK.STL"/>
    <mesh name="RAR_FOOT_LINK" file="RAR_FOOT_LINK.STL"/>
    <mesh name="RBL_ABAD_LINK" file="RBL_ABAD_LINK.STL"/>
    <mesh name="RBL_HIP_LINK" file="RBL_HIP_LINK.STL"/>
    <mesh name="RBL_KNEE_LINK" file="RBL_KNEE_LINK.STL"/>
    <mesh name="RBL_FOOT_LINK" file="RBL_FOOT_LINK.STL"/>
  </asset>
  <worldbody>
    <body name="BASE_LINK" childclass="zgwt" pos="0 0 0.45">
      <inertial pos="0.002176 0.011832 -0.009523" mass="20.25" fullinertia="0.120345 0.937020 0.987983 0.000149 -0.003415 0.001455"/>
      <freejoint/>
      <site name="imu" pos="0 0 0"/>
      <geom class="visual" mesh="BASE_LINK_0" material="body_gray"/>
      <geom class="visual" mesh="BASE_LINK_1" material="body_gray"/>
      <geom class="visual" mesh="BASE_LINK_2" material="body_gray"/>
      <geom class="visual" mesh="BASE_LINK_3" material="body_gray"/>
      <geom class="visual" mesh="BASE_LINK_4" material="body_gray"/>
      <geom class="visual" mesh="BASE_LINK_5" material="body_gray"/>
      <geom class="visual" mesh="BASE_LINK_6" material="body_gray"/>
      <geom class="visual" mesh="BASE_LINK_7" material="body_gray"/>
      <geom class="collision" pos="0.41 0 0" euler="0 0 0" type="box" size="0.05 0.05 0.08"/>
      <geom class="collision" pos="0 0 0" euler="0 0 0" type="box" size="0.2 0.11 0.08"/>
      <geom class="collision" pos="-0.41 0 0" euler="0 0 0" type="box" size="0.05 0.05 0.08"/>
      <body name="FAR_ABAD_LINK" childclass="zgwt" pos="0.272 -0.065 0.0002" euler="0 0 0">
        <inertial pos="0.030211 -0.015926 4.7238E-07" mass="0.26957" fullinertia="0.00020169 0.00029273 0.00025789 7.0404E-05 2.0546E-09 1.5E-09"/>
        <joint name="FAR_ABAD_JOINT" axis="1 0 0" range="-0.697 0.523"/>
        <geom class="visual" mesh="FAR_ABAD_LINK" material="cream"/>
        <body name="FAR_HIP_LINK" childclass="zgwt" pos="0.0575 -0.039 0" euler="0 0 0">
          <inertial pos="0.000248 -0.054095 -0.124371" mass="2.6525" fullinertia="0.042044 0.041643 0.002984 -0.000008 -0.000080 -0.005443"/>
          <joint name="FAR_HIP_JOINT" axis="0 1 0" range="-2.443 2.443"/>
          <geom class="visual" mesh="FAR_HIP_LINK" material="body_gray"/>
          <geom class="collision" pos="0 -0.04 0" euler="1.57 0 0" type="cylinder" size="0.04 0.04"/>
          <geom class="collision" pos="0 -0.06 -0.125" euler="0 0 0" type="box" size="0.03 0.015 0.075"/>
          <body name="FAR_KNEE_LINK" childclass="zgwt" pos="0 -0.0442 -0.26" euler="0 0 0">
            <inertial pos="9.0281E-05 -0.024369 -0.17395" mass="1.5888" fullinertia="0.022185 0.022093 0.001572 -0.000003 0.000012 -0.000132"/>
            <joint name="FAR_KNEE_JOINT" axis="0 1 0" range="-2.801 2.801"/>
            <geom class="visual" mesh="FAR_KNEE_LINK" material="body_gray"/>
            <geom class="collision" pos="0 -0.035 0" euler="1.57 0 0" type="cylinder" size="0.04 0.05"/>
            <geom class="collision" pos="0.0 -0.01 -0.14" euler="0 -0.0 0" type="box" size="0.02 0.02 0.085"/>
            <geom class="collision" pos="0 -0.01 -0.28" euler="1.57 0 0" type="cylinder" size="0.04 0.015"/>
            <body name="FAR_FOOT_LINK" childclass="zgwt" pos="0 -0.0592 -0.28" euler="0 0 0">
              <inertial pos="-0.000000 -0.007766 -1.0061E-06" mass="0.68796" fullinertia="0.0022048 0.0041699 0.0022106 1.0664E-10 1.131E-06 7.6444E-11"/>
              <joint name="FAR_FOOT_JOINT" axis="0 1 0"/>
              <geom class="visual" mesh="FAR_FOOT_LINK" material="dark"/>
              <geom class="collision" pos="0 -0.01 0" euler="1.5707963267948966 0 0" type="cylinder" size="0.095 0.02"/>
            </body>
          </body>
        </body>
      </body>
      <body name="FBL_ABAD_LINK" childclass="zgwt" pos="0.272 0.065 0.0002" euler="0 0 0">
        <inertial pos="0.030211 0.015926 2.3073E-06" mass="0.26957" fullinertia="0.00020169 0.00029273 0.00025789 -7.0404E-05 1.4342E-08 7.5809E-09"/>
        <joint name="FBL_ABAD_JOINT" axis="1 0 0" range="-0.523 0.697"/>
        <geom class="visual" mesh="FBL_ABAD_LINK" material="cream"/>
        <body name="FBL_HIP_LINK" childclass="zgwt" pos="0.0575 0.039 0" euler="0.00017453 0 0">
          <inertial pos="-0.00024776 0.054095 -0.12437" mass="2.6525" fullinertia="0.042044 0.041643 0.002984 -0.000008 0.000080 0.005443"/>
          <joint name="FBL_HIP_JOINT" axis="0 1 0" range="-2.443 2.443"/>
          <geom class="visual" mesh="FBL_HIP_LINK" material="body_gray"/>
          <geom class="collision" pos="0 0.04 0" euler="1.57 0 0" type="cylinder" size="0.04 0.04"/>
          <geom class="collision" pos="0 0.06 -0.125" euler="0 0 0" type="box" size="0.03 0.015 0.075"/>
          <body name="FBL_KNEE_LINK" childclass="zgwt" pos="0 0.0442 -0.26" euler="0 0 0">
            <inertial pos="-9.0281E-05 0.024369 -0.17395" mass="1.5888" fullinertia="0.022185 0.022093 0.001572 -0.000003 -0.000012 0.000132"/>
            <joint name="FBL_KNEE_JOINT" axis="0 1 0" range="-2.801 2.801"/>
            <geom class="visual" mesh="FBL_KNEE_LINK" material="body_gray"/>
            <geom class="collision" pos="0 0.035 0" euler="1.57 0 0" type="cylinder" size="0.04 0.05"/>
            <geom class="collision" pos="0.0 0.01 -0.14" euler="0 -0.0 0" type="box" size="0.02 0.02 0.085"/>
            <geom class="collision" pos="0 0.01 -0.28" euler="1.57 0 0" type="cylinder" size="0.04 0.015"/>
            <body name="FBL_FOOT_LINK" childclass="zgwt" pos="0 0.0592 -0.28" euler="0 0 0">
              <inertial pos="2.0302E-07 0.007766 -1.006E-06" mass="0.68796" fullinertia="0.0022048 0.0041699 0.0022106 1.0716E-10 -1.131E-06 7.6787E-11"/>
              <joint name="FBL_FOOT_JOINT" axis="0 1 0"/>
              <geom class="visual" mesh="FBL_FOOT_LINK" material="dark"/>
              <geom class="collision" pos="0 0.01 0" euler="1.5707963267948966 0 0" type="cylinder" size="0.095 0.02"/>
            </body>
          </body>
        </body>
      </body>
      <body name="RAR_ABAD_LINK" childclass="zgwt" pos="-0.272 -0.065 0.0002" euler="0 0 0">
        <inertial pos="-0.030211 -0.015926 -4.7238E-07" mass="0.26957" fullinertia="0.00020169 0.00029273 0.00025789 -7.0404E-05 2.0546E-09 1.5E-09"/>
        <joint name="RAR_ABAD_JOINT" axis="1 0 0" range="-0.697 0.523"/>
        <geom class="visual" mesh="RAR_ABAD_LINK" material="cream"/>
        <body name="RAR_HIP_LINK" childclass="zgwt" pos="-0.0575 -0.039 0" euler="0 0 0">
          <inertial pos="0.00024776 -0.054095 -0.12437" mass="2.6525" fullinertia="0.042044 0.041643 0.002984 -0.000008 -0.000080 -0.005443"/>
          <joint name="RAR_HIP_JOINT" axis="0 1 0" range="-2.443 2.443"/>
          <geom class="visual" mesh="RAR_HIP_LINK" material="body_gray"/>
          <geom class="collision" pos="0 -0.04 0" euler="1.57 0 0" type="cylinder" size="0.04 0.04"/>
          <geom class="collision" pos="0 -0.06 -0.125" euler="0 0 0" type="box" size="0.03 0.015 0.075"/>
          <body name="RAR_KNEE_LINK" childclass="zgwt" pos="0 -0.0442 -0.26" euler="0 0 0">
            <inertial pos="9.0281E-05 -0.024369 -0.17395" mass="1.5888" fullinertia="0.022185 0.022093 0.001572 -0.000003 0.000012 -0.000132"/>
            <joint name="RAR_KNEE_JOINT" axis="0 1 0" range="-2.801 2.801"/>
            <geom class="visual" mesh="RAR_KNEE_LINK" material="body_gray"/>
            <geom class="collision" pos="0 -0.035 0" euler="1.57 0 0" type="cylinder" size="0.04 0.05"/>
            <geom class="collision" pos="0.0 -0.01 -0.14" euler="0 -0.0 0" type="box" size="0.02 0.02 0.085"/>
            <geom class="collision" pos="0 -0.01 -0.28" euler="1.57 0 0" type="cylinder" size="0.04 0.015"/>
            <body name="RAR_FOOT_LINK" childclass="zgwt" pos="0 -0.0592 -0.28" euler="0 0 0">
              <inertial pos="-2.0294E-07 -0.007766 -1.006E-06" mass="0.68796" fullinertia="0.0022048 0.0041699 0.0022106 1.0789E-10 1.131E-06 7.6641E-11"/>
              <joint name="RAR_FOOT_JOINT" axis="0 1 0"/>
              <geom class="visual" mesh="RAR_FOOT_LINK" material="dark"/>
              <geom class="collision" pos="0 -0.01 0" euler="1.5707963267948966 0 0" type="cylinder" size="0.095 0.02"/>
            </body>
          </body>
        </body>
      </body>
      <body name="RBL_ABAD_LINK" childclass="zgwt" pos="-0.272 0.065 0.0002" euler="0 0 0">
        <inertial pos="-0.030211 0.015926 0.000000" mass="0.26957" fullinertia="0.00020169 0.00029273 0.00025879 0.000070 0.000000 0.000000"/>
        <joint name="RBL_ABAD_JOINT" axis="1 0 0" range="-0.523 0.697"/>
        <geom class="visual" mesh="RBL_ABAD_LINK" material="cream"/>
        <body name="RBL_HIP_LINK" childclass="zgwt" pos="-0.0575 0.039 0" euler="0 0 0">
          <inertial pos="-0.00024776 0.054095 -0.12437" mass="2.6525" fullinertia="0.042044 0.041643 0.002984 -0.000008 0.000080 0.005443"/>
          <joint name="RBL_HIP_JOINT" axis="0 1 0" range="-2.443 2.443"/>
          <geom class="visual" mesh="RBL_HIP_LINK" material="body_gray"/>
          <geom class="collision" pos="0 0.04 0" euler="1.57 0 0" type="cylinder" size="0.04 0.04"/>
          <geom class="collision" pos="0 0.06 -0.125" euler="0 0 0" type="box" size="0.03 0.015 0.075"/>
          <body name="RBL_KNEE_LINK" childclass="zgwt" pos="0 0.0442 -0.26" euler="0 0 0">
            <inertial pos="-9.0281E-05 0.024369 -0.17395" mass="1.5888" fullinertia="0.022185 0.022093 0.001572 -0.000003 -0.000012 0.000132"/>
            <joint name="RBL_KNEE_JOINT" axis="0 1 0" range="-2.801 2.801"/>
            <geom class="visual" mesh="RBL_KNEE_LINK" material="body_gray"/>
            <geom class="collision" pos="0 0.035 0" euler="1.57 0 0" type="cylinder" size="0.04 0.05"/>
            <geom class="collision" pos="0.0 0.01 -0.14" euler="0 -0.0 0" type="box" size="0.02 0.02 0.085"/>
            <geom class="collision" pos="0 0.01 -0.28" euler="1.57 0 0" type="cylinder" size="0.04 0.015"/>
            <body name="RBL_FOOT_LINK" childclass="zgwt" pos="0 0.0592 -0.28" euler="0 0 0">
              <inertial pos="2.0294E-07 0.007766 -1.006E-06" mass="0.68796" fullinertia="0.0022048 0.0041699 0.0022106 1.0789E-10 -1.131E-06 7.6642E-11"/>
              <joint name="RBL_FOOT_JOINT" axis="0 1 0"/>
              <geom class="visual" mesh="RBL_FOOT_LINK" material="dark"/>
              <geom class="collision" pos="0 0.01 0" euler="1.5707963267948966 0 0" type="cylinder" size="0.095 0.02"/>
            </body>
          </body>
        </body>
      </body>
    </body>
  </worldbody>
  <actuator>
    <motor name="FAR_ABAD" joint="FAR_ABAD_JOINT" ctrlrange="-180 180"/>
    <motor name="FAR_HIP" joint="FAR_HIP_JOINT" ctrlrange="-180 180"/>
    <motor name="FAR_KNEE" joint="FAR_KNEE_JOINT" ctrlrange="-180 180"/>
    <motor name="FAR_FOOT" joint="FAR_FOOT_JOINT" ctrlrange="-28 28"/>
    <motor name="FBL_ABAD" joint="FBL_ABAD_JOINT" ctrlrange="-180 180"/>
    <motor name="FBL_HIP" joint="FBL_HIP_JOINT" ctrlrange="-180 180"/>
    <motor name="FBL_KNEE" joint="FBL_KNEE_JOINT" ctrlrange="-180 180"/>
    <motor name="FBL_FOOT" joint="FBL_FOOT_JOINT" ctrlrange="-28 28"/>
    <motor name="RAR_ABAD" joint="RAR_ABAD_JOINT" ctrlrange="-180 180"/>
    <motor name="RAR_HIP" joint="RAR_HIP_JOINT" ctrlrange="-180 180"/>
    <motor name="RAR_KNEE" joint="RAR_KNEE_JOINT" ctrlrange="-180 180"/>
    <motor name="RAR_FOOT" joint="RAR_FOOT_JOINT" ctrlrange="-28 28"/>
    <motor name="RBL_ABAD" joint="RBL_ABAD_JOINT" ctrlrange="-180 180"/>
    <motor name="RBL_HIP" joint="RBL_HIP_JOINT" ctrlrange="-180 180"/>
    <motor name="RBL_KNEE" joint="RBL_KNEE_JOINT" ctrlrange="-180 180"/>
    <motor name="RBL_FOOT" joint="RBL_FOOT_JOINT" ctrlrange="-28 28"/>
  </actuator>
  <sensor>
    <jointpos name="FAR_ABAD_JOINT_pos" joint="FAR_ABAD_JOINT"/>
    <jointpos name="FAR_HIP_JOINT_pos" joint="FAR_HIP_JOINT"/>
    <jointpos name="FAR_KNEE_JOINT_pos" joint="FAR_KNEE_JOINT"/>
    <jointpos name="FAR_FOOT_JOINT_pos" joint="FAR_FOOT_JOINT"/>
    <jointpos name="FBL_ABAD_JOINT_pos" joint="FBL_ABAD_JOINT"/>
    <jointpos name="FBL_HIP_JOINT_pos" joint="FBL_HIP_JOINT"/>
    <jointpos name="FBL_KNEE_JOINT_pos" joint="FBL_KNEE_JOINT"/>
    <jointpos name="FBL_FOOT_JOINT_pos" joint="FBL_FOOT_JOINT"/>
    <jointpos name="RAR_ABAD_JOINT_pos" joint="RAR_ABAD_JOINT"/>
    <jointpos name="RAR_HIP_JOINT_pos" joint="RAR_HIP_JOINT"/>
    <jointpos name="RAR_KNEE_JOINT_pos" joint="RAR_KNEE_JOINT"/>
    <jointpos name="RAR_FOOT_JOINT_pos" joint="RAR_FOOT_JOINT"/>
    <jointpos name="RBL_ABAD_JOINT_pos" joint="RBL_ABAD_JOINT"/>
    <jointpos name="RBL_HIP_JOINT_pos" joint="RBL_HIP_JOINT"/>
    <jointpos name="RBL_KNEE_JOINT_pos" joint="RBL_KNEE_JOINT"/>
    <jointpos name="RBL_FOOT_JOINT_pos" joint="RBL_FOOT_JOINT"/>
    <jointvel name="FAR_ABAD_JOINT_vel" joint="FAR_ABAD_JOINT"/>
    <jointvel name="FAR_HIP_JOINT_vel" joint="FAR_HIP_JOINT"/>
    <jointvel name="FAR_KNEE_JOINT_vel" joint="FAR_KNEE_JOINT"/>
    <jointvel name="FAR_FOOT_JOINT_vel" joint="FAR_FOOT_JOINT"/>
    <jointvel name="FBL_ABAD_JOINT_vel" joint="FBL_ABAD_JOINT"/>
    <jointvel name="FBL_HIP_JOINT_vel" joint="FBL_HIP_JOINT"/>
    <jointvel name="FBL_KNEE_JOINT_vel" joint="FBL_KNEE_JOINT"/>
    <jointvel name="FBL_FOOT_JOINT_vel" joint="FBL_FOOT_JOINT"/>
    <jointvel name="RAR_ABAD_JOINT_vel" joint="RAR_ABAD_JOINT"/>
    <jointvel name="RAR_HIP_JOINT_vel" joint="RAR_HIP_JOINT"/>
    <jointvel name="RAR_KNEE_JOINT_vel" joint="RAR_KNEE_JOINT"/>
    <jointvel name="RAR_FOOT_JOINT_vel" joint="RAR_FOOT_JOINT"/>
    <jointvel name="RBL_ABAD_JOINT_vel" joint="RBL_ABAD_JOINT"/>
    <jointvel name="RBL_HIP_JOINT_vel" joint="RBL_HIP_JOINT"/>
    <jointvel name="RBL_KNEE_JOINT_vel" joint="RBL_KNEE_JOINT"/>
    <jointvel name="RBL_FOOT_JOINT_vel" joint="RBL_FOOT_JOINT"/>
    <jointactuatorfrc name="FAR_ABAD_JOINT_torque" joint="FAR_ABAD_JOINT"/>
    <jointactuatorfrc name="FAR_HIP_JOINT_torque" joint="FAR_HIP_JOINT"/>
    <jointactuatorfrc name="FAR_KNEE_JOINT_torque" joint="FAR_KNEE_JOINT"/>
    <jointactuatorfrc name="FAR_FOOT_JOINT_torque" joint="FAR_FOOT_JOINT"/>
    <jointactuatorfrc name="FBL_ABAD_JOINT_torque" joint="FBL_ABAD_JOINT"/>
    <jointactuatorfrc name="FBL_HIP_JOINT_torque" joint="FBL_HIP_JOINT"/>
    <jointactuatorfrc name="FBL_KNEE_JOINT_torque" joint="FBL_KNEE_JOINT"/>
    <jointactuatorfrc name="FBL_FOOT_JOINT_torque" joint="FBL_FOOT_JOINT"/>
    <jointactuatorfrc name="RAR_ABAD_JOINT_torque" joint="RAR_ABAD_JOINT"/>
    <jointactuatorfrc name="RAR_HIP_JOINT_torque" joint="RAR_HIP_JOINT"/>
    <jointactuatorfrc name="RAR_KNEE_JOINT_torque" joint="RAR_KNEE_JOINT"/>
    <jointactuatorfrc name="RAR_FOOT_JOINT_torque" joint="RAR_FOOT_JOINT"/>
    <jointactuatorfrc name="RBL_ABAD_JOINT_torque" joint="RBL_ABAD_JOINT"/>
    <jointactuatorfrc name="RBL_HIP_JOINT_torque" joint="RBL_HIP_JOINT"/>
    <jointactuatorfrc name="RBL_KNEE_JOINT_torque" joint="RBL_KNEE_JOINT"/>
    <jointactuatorfrc name="RBL_FOOT_JOINT_torque" joint="RBL_FOOT_JOINT"/>
    <framequat name="imu_quat" objtype="site" objname="imu" noise="0.0"/>
    <gyro name="imu_gyro" site="imu" noise="0.0"/>
    <accelerometer name="imu_acc" site="imu"/>
    <framepos name="frame_pos" objtype="site" objname="imu"/>
    <framelinvel name="frame_vel" objtype="site" objname="imu"/>
  </sensor>
</mujoco>
